Workbook

Sheet Resumen
A1: CONTROL AUTOMÁTICO DE ASISTENCIA - DATASET BASE PARA JENKINS
A2: Objetivo | B2: Base de datos lista para detectar faltas, tardanzas, incidencias y generar un PDF automático.
A3: Periodo | B3: Febrero 2026
A5: Total de registros | B5: =COUNTA(Asistencia_Febrero_2026!A2:A361) -> 360 | D5: Estado | E5: Cantidad
A6: Asistencias | B6: =COUNTIF(Asistencia_Febrero_2026!L2:L361,"Asistencia") -> 293 | D6: Asistencia | E6: =COUNTIF(Asistencia_Febrero_2026!L2:L361,"Asistencia") -> 293
A7: Tardanzas | B7: =COUNTIF(Asistencia_Febrero_2026!L2:L361,"Tardanza") -> 42 | D7: Tardanza | E7: =COUNTIF(Asistencia_Febrero_2026!L2:L361,"Tardanza") -> 42
A8: Faltas | B8: =COUNTIF(Asistencia_Febrero_2026!L2:L361,"Falta") -> 7 | D8: Falta | E8: =COUNTIF(Asistencia_Febrero_2026!L2:L361,"Falta") -> 7
A9: Permisos | B9: =COUNTIF(Asistencia_Febrero_2026!L2:L361,"Permiso") -> 8 | D9: Permiso | E9: =COUNTIF(Asistencia_Febrero_2026!L2:L361,"Permiso") -> 8
A10: Vacaciones | B10: =COUNTIF(Asistencia_Febrero_2026!L2:L361,"Vacaciones") -> 10 | D10: Vacaciones | E10: =COUNTIF(Asistencia_Febrero_2026!L2:L361,"Vacaciones") -> 10
A11: Incidencias | B11: =SUM(B7:B10) -> 67
A12: Tasa de incidencia | B12: =B11/B5 -> 0.18611111
A14: Área | B14: Registros | C14: Asistencias | D14: Tardanzas | E14: Faltas | F14: Permisos | G14: Vacaciones
A15: Comercial | B15: =COUNTIF(Asistencia_Febrero_2026!E:E,A15) -> 80 | C15: =COUNTIFS(Asistencia_Febrero_2026!E:E,A15,Asistencia_Febrero_2026!L:L,"Asistencia") -> 67 | D15: =COUNTIFS(Asistencia_Febrero_2026!E:E,A15,Asistencia_Febrero_2026!L:L,"Tardanza") -> 9 | E15: =COUNTIFS(Asistencia_Febrero_2026!E:E,A15,Asistencia_Febrero_2026!L:L,"Falta") -> 2 | F15: =COUNTIFS(Asistencia_Febrero_2026!E:E,A15,Asistencia_Febrero_2026!L:L,"Permiso") -> 2 | G15: =COUNTIFS(Asistencia_Febrero_2026!E:E,A15,Asistencia_Febrero_2026!L:L,"Vacaciones") -> 0
A16: Finanzas | B16: =COUNTIF(Asistencia_Febrero_2026!E:E,A16) -> 60 | C16: =COUNTIFS(Asistencia_Febrero_2026!E:E,A16,Asistencia_Febrero_2026!L:L,"Asistencia") -> 47 | D16: =COUNTIFS(Asistencia_Febrero_2026!E:E,A16,Asistencia_Febrero_2026!L:L,"Tardanza") -> 2 | E16: =COUNTIFS(Asistencia_Febrero_2026!E:E,A16,Asistencia_Febrero_2026!L:L,"Falta") -> 1 | F16: =COUNTIFS(Asistencia_Febrero_2026!E:E,A16,Asistencia_Febrero_2026!L:L,"Permiso") -> 0 | G16: =COUNTIFS(Asistencia_Febrero_2026!E:E,A16,Asistencia_Febrero_2026!L:L,"Vacaciones") -> 10
A17: Operaciones | B17: =COUNTIF(Asistencia_Febrero_2026!E:E,A17) -> 80 | C17: =COUNTIFS(Asistencia_Febrero_2026!E:E,A17,Asistencia_Febrero_2026!L:L,"Asistencia") -> 57 | D17: =COUNTIFS(Asistencia_Febrero_2026!E:E,A17,Asistencia_Febrero_2026!L:L,"Tardanza") -> 16 | E17: =COUNTIFS(Asistencia_Febrero_2026!E:E,A17,Asistencia_Febrero_2026!L:L,"Falta") -> 4 | F17: =COUNTIFS(Asistencia_Febrero_2026!E:E,A17,Asistencia_Febrero_2026!L:L,"Permiso") -> 3 | G17: =COUNTIFS(Asistencia_Febrero_2026!E:E,A17,Asistencia_Febrero_2026!L:L,"Vacaciones") -> 0
A18: RRHH | B18: =COUNTIF(Asistencia_Febrero_2026!E:E,A18) -> 60 | C18: =COUNTIFS(Asistencia_Febrero_2026!E:E,A18,Asistencia_Febrero_2026!L:L,"Asistencia") -> 55 | D18: =COUNTIFS(Asistencia_Febrero_2026!E:E,A18,Asistencia_Febrero_2026!L:L,"Tardanza") -> 5 | E18: =COUNTIFS(Asistencia_Febrero_2026!E:E,A18,Asistencia_Febrero_2026!L:L,"Falta") -> 0 | F18: =COUNTIFS(Asistencia_Febrero_2026!E:E,A18,Asistencia_Febrero_2026!L:L,"Permiso") -> 0 | G18: =COUNTIFS(Asistencia_Febrero_2026!E:E,A18,Asistencia_Febrero_2026!L:L,"Vacaciones") -> 0
A19: TI | B19: =COUNTIF(Asistencia_Febrero_2026!E:E,A19) -> 80 | C19: =COUNTIFS(Asistencia_Febrero_2026!E:E,A19,Asistencia_Febrero_2026!L:L,"Asistencia") -> 67 | D19: =COUNTIFS(Asistencia_Febrero_2026!E:E,A19,Asistencia_Febrero_2026!L:L,"Tardanza") -> 10 | E19: =COUNTIFS(Asistencia_Febrero_2026!E:E,A19,Asistencia_Febrero_2026!L:L,"Falta") -> 0 | F19: =COUNTIFS(Asistencia_Febrero_2026!E:E,A19,Asistencia_Febrero_2026!L:L,"Permiso") -> 3 | G19: =COUNTIFS(Asistencia_Febrero_2026!E:E,A19,Asistencia_Febrero_2026!L:L,"Vacaciones") -> 0
A22: ID_Empleado | B22: Nombre | C22: Área | D22: Tardanzas | E22: Faltas | F22: Permisos | G22: Vacaciones | H22: Total incidencias | I22: Asistencia %
A23: EMP001 | B23: Ana Torres | C23: RRHH | D23: =COUNTIFS(Asistencia_Febrero_2026!C:C,A23,Asistencia_Febrero_2026!L:L,"Tardanza") -> 2 | E23: =COUNTIFS(Asistencia_Febrero_2026!C:C,A23,Asistencia_Febrero_2026!L:L,"Falta") -> 0 | F23: =COUNTIFS(Asistencia_Febrero_2026!C:C,A23,Asistencia_Febrero_2026!L:L,"Permiso") -> 0 | G23: =COUNTIFS(Asistencia_Febrero_2026!C:C,A23,Asistencia_Febrero_2026!L:L,"Vacaciones") -> 0 | H23: =SUM(D23:G23) -> 2 | I23: =1-(H23/Parametros!$B$6) -> 0.9
A24: EMP002 | B24: Luis Mendoza | C24: Operaciones | D24: =COUNTIFS(Asistencia_Febrero_2026!C:C,A24,Asistencia_Febrero_2026!L:L,"Tardanza") -> 3 | E24: =COUNTIFS(Asistencia_Febrero_2026!C:C,A24,Asistencia_Febrero_2026!L:L,"Falta") -> 0 | F24: =COUNTIFS(Asistencia_Febrero_2026!C:C,A24,Asistencia_Febrero_2026!L:L,"Permiso") -> 1 | G24: =COUNTIFS(Asistencia_Febrero_2026!C:C,A24,Asistencia_Febrero_2026!L:L,"Vacaciones") -> 0 | H24: =SUM(D24:G24) -> 4 | I24: =1-(H24/Parametros!$B$6) -> 0.8
A25: EMP003 | B25: Carla Rojas | C25: Finanzas | D25: =COUNTIFS(Asistencia_Febrero_2026!C:C,A25,Asistencia_Febrero_2026!L:L,"Tardanza") -> 2 | E25: =COUNTIFS(Asistencia_Febrero_2026!C:C,A25,Asistencia_Febrero_2026!L:L,"Falta") -> 1 | F25: =COUNTIFS(Asistencia_Febrero_2026!C:C,A25,Asistencia_Febrero_2026!L:L,"Permiso") -> 0 | G25: =COUNTIFS(Asistencia_Febrero_2026!C:C,A25,Asistencia_Febrero_2026!L:L,"Vacaciones") -> 0 | H25: =SUM(D25:G25) -> 3 | I25: =1-(H25/Parametros!$B$6) -> 0.85
A26: EMP004 | B26: Jorge Salazar | C26: TI | D26: =COUNTIFS(Asistencia_Febrero_2026!C:C,A26,Asistencia_Febrero_2026!L:L,"Tardanza") -> 2 | E26: =COUNTIFS(Asistencia_Febrero_2026!C:C,A26,Asistencia_Febrero_2026!L:L,"Falta") -> 0 | F26: =COUNTIFS(Asistencia_Febrero_2026!C:C,A26,Asistencia_Febrero_2026!L:L,"Permiso") -> 1 | G26: =COUNTIFS(Asistencia_Febrero_2026!C:C,A26,Asistencia_Febrero_2026!L:L,"Vacaciones") -> 0 | H26: =SUM(D26:G26) -> 3 | I26: =1-(H26/Parametros!$B$6) -> 0.85
A27: EMP005 | B27: María Paredes | C27: Comercial | D27: =COUNTIFS(Asistencia_Febrero_2026!C:C,A27,Asistencia_Febrero_2026!L:L,"Tardanza") -> 4 | E27: =COUNTIFS(Asistencia_Febrero_2026!C:C,A27,Asistencia_Febrero_2026!L:L,"Falta") -> 1 | F27: =COUNTIFS(Asistencia_Febrero_2026!C:C,A27,Asistencia_Febrero_2026!L:L,"Permiso") -> 0 | G27: =COUNTIFS(Asistencia_Febrero_2026!C:C,A27,Asistencia_Febrero_2026!L:L,"Vacaciones") -> 0 | H27: =SUM(D27:G27) -> 5 | I27: =1-(H27/Parametros!$B$6) -> 0.75
A28: EMP006 | B28: Pedro Huamán | C28: Operaciones | D28: =COUNTIFS(Asistencia_Febrero_2026!C:C,A28,Asistencia_Febrero_2026!L:L,"Tardanza") -> 7 | E28: =COUNTIFS(Asistencia_Febrero_2026!C:C,A28,Asistencia_Febrero_2026!L:L,"Falta") -> 1 | F28: =COUNTIFS(Asistencia_Febrero_2026!C:C,A28,Asistencia_Febrero_2026!L:L,"Permiso") -> 1 | G28: =COUNTIFS(Asistencia_Febrero_2026!C:C,A28,Asistencia_Febrero_2026!L:L,"Vacaciones") -> 0 | H28: =SUM(D28:G28) -> 9 | I28: =1-(H28/Parametros!$B$6) -> 0.55
A29: EMP007 | B29: Daniela Núñez | C29: RRHH | D29: =COUNTIFS(Asistencia_Febrero_2026!C:C,A29,Asistencia_Febrero_2026!L:L,"Tardanza") -> 2 | E29: =COUNTIFS(Asistencia_Febrero_2026!C:C,A29,Asistencia_Febrero_2026!L:L,"Falta") -> 0 | F29: =COUNTIFS(Asistencia_Febrero_2026!C:C,A29,Asistencia_Febrero_2026!L:L,"Permiso") -> 0 | G29: =COUNTIFS(Asistencia_Febrero_2026!C:C,A29,Asistencia_Febrero_2026!L:L,"Vacaciones") -> 0 | H29: =SUM(D29:G29) -> 2 | I29: =1-(H29/Parametros!$B$6) -> 0.9
A30: EMP008 | B30: Carlos Mejía | C30: TI | D30: =COUNTIFS(Asistencia_Febrero_2026!C:C,A30,Asistencia_Febrero_2026!L:L,"Tardanza") -> 4 | E30: =COUNTIFS(Asistencia_Febrero_2026!C:C,A30,Asistencia_Febrero_2026!L:L,"Falta") -> 0 | F30: =COUNTIFS(Asistencia_Febrero_2026!C:C,A30,Asistencia_Febrero_2026!L:L,"Permiso") -> 1 | G30: =COUNTIFS(Asistencia_Febrero_2026!C:C,A30,Asistencia_Febrero_2026!L:L,"Vacaciones") -> 0 | H30: =SUM(D30:G30) -> 5 | I30: =1-(H30/Parametros!$B$6) -> 0.75
A31: EMP009 | B31: Valeria Soto | C31: Finanzas | D31: =COUNTIFS(Asistencia_Febrero_2026!C:C,A31,Asistencia_Febrero_2026!L:L,"Tardanza") -> 0 | E31: =COUNTIFS(Asistencia_Febrero_2026!C:C,A31,Asistencia_Febrero_2026!L:L,"Falta") -> 0 | F31: =COUNTIFS(Asistencia_Febrero_2026!C:C,A31,Asistencia_Febrero_2026!L:L,"Permiso") -> 0 | G31: =COUNTIFS(Asistencia_Febrero_2026!C:C,A31,Asistencia_Febrero_2026!L:L,"Vacaciones") -> 5 | H31: =SUM(D31:G31) -> 5 | I31: =1-(H31/Parametros!$B$6) -> 0.75
A32: EMP010 | B32: Miguel Chávez | C32: Comercial | D32: =COUNTIFS(Asistencia_Febrero_2026!C:C,A32,Asistencia_Febrero_2026!L:L,"Tardanza") -> 3 | E32: =COUNTIFS(Asistencia_Febrero_2026!C:C,A32,Asistencia_Febrero_2026!L:L,"Falta") -> 1 | F32: =COUNTIFS(Asistencia_Febrero_2026!C:C,A32,Asistencia_Febrero_2026!L:L,"Permiso") -> 0 | G32: =COUNTIFS(Asistencia_Febrero_2026!C:C,A32,Asistencia_Febrero_2026!L:L,"Vacaciones") -> 0 | H32: =SUM(D32:G32) -> 4 | I32: =1-(H32/Parametros!$B$6) -> 0.8
A33: EMP011 | B33: Sofía Quispe | C33: Operaciones | D33: =COUNTIFS(Asistencia_Febrero_2026!C:C,A33,Asistencia_Febrero_2026!L:L,"Tardanza") -> 4 | E33: =COUNTIFS(Asistencia_Febrero_2026!C:C,A33,Asistencia_Febrero_2026!L:L,"Falta") -> 2 | F33: =COUNTIFS(Asistencia_Febrero_2026!C:C,A33,Asistencia_Febrero_2026!L:L,"Permiso") -> 1 | G33: =COUNTIFS(Asistencia_Febrero_2026!C:C,A33,Asistencia_Febrero_2026!L:L,"Vacaciones") -> 0 | H33: =SUM(D33:G33) -> 7 | I33: =1-(H33/Parametros!$B$6) -> 0.65
A34: EMP012 | B34: Ricardo León | C34: TI | D34: =COUNTIFS(Asistencia_Febrero_2026!C:C,A34,Asistencia_Febrero_2026!L:L,"Tardanza") -> 1 | E34: =COUNTIFS(Asistencia_Febrero_2026!C:C,A34,Asistencia_Febrero_2026!L:L,"Falta") -> 0 | F34: =COUNTIFS(Asistencia_Febrero_2026!C:C,A34,Asistencia_Febrero_2026!L:L,"Permiso") -> 1 | G34: =COUNTIFS(Asistencia_Febrero_2026!C:C,A34,Asistencia_Febrero_2026!L:L,"Vacaciones") -> 0 | H34: =SUM(D34:G34) -> 2 | I34: =1-(H34/Parametros!$B$6) -> 0.9
... A40: EMP018 | B40: Héctor Ramos | C40: TI | D40: =COUNTIFS(Asistencia_Febrero_2026!C:C,A40,Asistencia_Febrero_2026!L:L,"Tardanza") -> 3 | E40: =COUNTIFS(Asistencia_Febrero_2026!C:C,A40,Asistencia_Febrero_2026!L:L,"Falta") -> 0 | F40: =COUNTIFS(Asistencia_Febrero_2026!C:C,A40,Asistencia_Febrero_2026!L:L,"Permiso") -> 0 | G40: =COUNTIFS(Asistencia_Febrero_2026!C:C,A40,Asistencia_Febrero_2026!L:L,"Vacaciones") -> 0 | H40: =SUM(D40:G40) -> 3 | I40: =1-(H40/Parametros!$B$6) -> 0.85
A43: Nota | B43: La columna Minutos_Tardanza considera una tolerancia de 10 minutos según la hoja Parametros.

Sheet Parametros
A1: Parámetro | B1: Valor | C1: Descripción
A2: Periodo | B2: Febrero 2026 | C2: Mes base del dataset
A3: Hora_Entrada_Estandar | B3: 0.375 | C3: Horario estándar de ingreso
A4: Tolerancia_Tardanza | B4: 0.0069444444 | C4: Minutos permitidos antes de considerar tardanza
A5: Hora_Salida_Estandar | B5: 0.75 | C5: Horario estándar de salida
A6: Dias_Habiles_Considerados | B6: 20 | C6: Cantidad de días laborables del periodo
A7: Regla_Falta | B7: Sin marcación y sin permiso/vacaciones | C7: Criterio usado en el proyecto
A8: Regla_Incidencia | B8: Tardanza, Falta, Permiso o Vacaciones | C8: Clasificación para el resumen

Sheet Empleados
A1: ID_Empleado | B1: Nombre | C1: Área | D1: Cargo | E1: Sede | F1: Perfil_Riesgo
A2: EMP001 | B2: Ana Torres | C2: RRHH | D2: Analista de RRHH | E2: Lima | F2: Bajo
A3: EMP002 | B3: Luis Mendoza | C3: Operaciones | D3: Supervisor de Operaciones | E3: Lima | F3: Alto
A4: EMP003 | B4: Carla Rojas | C4: Finanzas | D4: Asistente Contable | E4: Lima | F4: Bajo
A5: EMP004 | B5: Jorge Salazar | C5: TI | D5: Soporte TI | E5: Lima | F5: Medio
A6: EMP005 | B6: María Paredes | C6: Comercial | D6: Ejecutiva Comercial | E6: Lima | F6: Medio
A7: EMP006 | B7: Pedro Huamán | C7: Operaciones | D7: Analista de Campo | E7: Callao | F7: Alto
A8: EMP007 | B8: Daniela Núñez | C8: RRHH | D8: Coordinadora de RRHH | E8: Lima | F8: Bajo
A9: EMP008 | B9: Carlos Mejía | C9: TI | D9: Desarrollador Junior | E9: Lima | F9: Medio
A10: EMP009 | B10: Valeria Soto | C10: Finanzas | D10: Analista de Tesorería | E10: Lima | F10: Bajo
A11: EMP010 | B11: Miguel Chávez | C11: Comercial | D11: Asesor de Ventas | E11: Surco | F11: Alto
A12: EMP011 | B12: Sofía Quispe | C12: Operaciones | D12: Asistente Operativo | E12: Callao | F12: Medio
... A19: EMP018 | B19: Héctor Ramos | C19: TI | D19: QA Tester | E19: Lima | F19: Medio

Sheet Asistencia_Febrero_2026
A1: Fecha | B1: Dia | C1: ID_Empleado | D1: Nombre | E1: Area | F1: Cargo | G1: Sede | H1: Hora_Entrada_Programada | I1: Hora_Entrada_Real | J1: Hora_Salida_Programada | K1: Hora_Salida_Real | L1: Estado | M1: Minutos_Tardanza | N1: Incidencia | O1: Observacion
A2: 46055 | B2: Lunes | C2: EMP001 | D2: Ana Torres | E2: RRHH | F2: Analista de RRHH | G2: Lima | H2: 0.375 | I2: 0.39444444 | J2: 0.75 | K2: 0.75486111 | L2: Tardanza | M2: =IF(OR(I2="",H2=""),"",MAX(0,ROUND((I2-H2-Parametros!$B$4)*1440,0))) -> 18 | N2: =IF(L2="Asistencia","Sin novedad",L2) -> Tardanza | O2: Demora de transporte
A3: 46055 | B3: Lunes | C3: EMP002 | D3: Luis Mendoza | E3: Operaciones | F3: Supervisor de Operaciones | G3: Lima | H3: 0.375 | I3: 0.40625 | J3: 0.75 | K3: 0.74791667 | L3: Tardanza | M3: =IF(OR(I3="",H3=""),"",MAX(0,ROUND((I3-H3-Parametros!$B$4)*1440,0))) -> 35 | N3: =IF(L3="Asistencia","Sin novedad",L3) -> Tardanza | O3: Tráfico
A4: 46055 | B4: Lunes | C4: EMP003 | D4: Carla Rojas | E4: Finanzas | F4: Asistente Contable | G4: Lima | H4: 0.375 | I4: 0.39166667 | J4: 0.75 | K4: 0.75416667 | L4: Tardanza | M4: =IF(OR(I4="",H4=""),"",MAX(0,ROUND((I4-H4-Parametros!$B$4)*1440,0))) -> 14 | N4: =IF(L4="Asistencia","Sin novedad",L4) -> Tardanza | O4: Tráfico
A5: 46055 | B5: Lunes | C5: EMP004 | D5: Jorge Salazar | E5: TI | F5: Soporte TI | G5: Lima | H5: 0.375 | I5: 0.37777778 | J5: 0.75 | K5: 0.76527778 | L5: Asistencia | M5: =IF(OR(I5="",H5=""),"",MAX(0,ROUND((I5-H5-Parametros!$B$4)*1440,0))) -> 0 | N5: =IF(L5="Asistencia","Sin novedad",L5) -> Sin novedad | O5: Registro biométrico correcto
A6: 46055 | B6: Lunes | C6: EMP005 | D6: María Paredes | E6: Comercial | F6: Ejecutiva Comercial | G6: Lima | H6: 0.375 | I6: 0.37986111 | J6: 0.75 | K6: 0.74166667 | L6: Asistencia | M6: =IF(OR(I6="",H6=""),"",MAX(0,ROUND((I6-H6-Parametros!$B$4)*1440,0))) -> 0 | N6: =IF(L6="Asistencia","Sin novedad",L6) -> Sin novedad | O6: Sin novedades
A7: 46055 | B7: Lunes | C7: EMP006 | D7: Pedro Huamán | E7: Operaciones | F7: Analista de Campo | G7: Callao | H7: 0.375 | I7: 0.36527778 | J7: 0.75 | K7: 0.75069444 | L7: Asistencia | M7: =IF(OR(I7="",H7=""),"",MAX(0,ROUND((I7-H7-Parametros!$B$4)*1440,0))) -> 0 | N7: =IF(L7="Asistencia","Sin novedad",L7) -> Sin novedad | O7: Registro biométrico correcto
A8: 46055 | B8: Lunes | C8: EMP007 | D8: Daniela Núñez | E8: RRHH | F8: Coordinadora de RRHH | G8: Lima | H8: 0.375 | I8: 0.37013889 | J8: 0.75 | K8: 0.75694444 | L8: Asistencia | M8: =IF(OR(I8="",H8=""),"",MAX(0,ROUND((I8-H8-Parametros!$B$4)*1440,0))) -> 0 | N8: =IF(L8="Asistencia","Sin novedad",L8) -> Sin novedad | O8: Jornada normal
A9: 46055 | B9: Lunes | C9: EMP008 | D9: Carlos Mejía | E9: TI | F9: Desarrollador Junior | G9: Lima | H9: 0.375 | I9: 0.40277778 | J9: 0.75 | K9: 0.76805556 | L9: Tardanza | M9: =IF(OR(I9="",H9=""),"",MAX(0,ROUND((I9-H9-Parametros!$B$4)*1440,0))) -> 30 | N9: =IF(L9="Asistencia","Sin novedad",L9) -> Tardanza | O9: Demora de transporte
A10: 46055 | B10: Lunes | C10: EMP009 | D10: Valeria Soto | E10: Finanzas | F10: Analista de Tesorería | G10: Lima | H10: 0.375 | I10: 0.37430556 | J10: 0.75 | K10: 0.75416667 | L10: Asistencia | M10: =IF(OR(I10="",H10=""),"",MAX(0,ROUND((I10-H10-Parametros!$B$4)*1440,0))) -> 0 | N10: =IF(L10="Asistencia","Sin novedad",L10) -> Sin novedad | O10: Jornada normal
A11: 46055 | B11: Lunes | C11: EMP010 | D11: Miguel Chávez | E11: Comercial | F11: Asesor de Ventas | G11: Surco | H11: 0.375 | I11: 0.375 | J11: 0.75 | K11: 0.75 | L11: Asistencia | M11: =IF(OR(I11="",H11=""),"",MAX(0,ROUND((I11-H11-Parametros!$B$4)*1440,0))) -> 0 | N11: =IF(L11="Asistencia","Sin novedad",L11) -> Sin novedad | O11: Jornada normal
A12: 46055 | B12: Lunes | C12: EMP011 | D12: Sofía Quispe | E12: Operaciones | F12: Asistente Operativo | G12: Callao | H12: 0.375 | I12: 0.37916667 | J12: 0.75 | K12: 0.75416667 | L12: Asistencia | M12: =IF(OR(I12="",H12=""),"",MAX(0,ROUND((I12-H12-Parametros!$B$4)*1440,0))) -> 0 | N12: =IF(L12="Asistencia","Sin novedad",L12) -> Sin novedad | O12: Sin novedades
A13: 46055 | B13: Lunes | C13: EMP012 | D13: Ricardo León | E13: TI | F13: Administrador de Sistemas | G13: Lima | H13: 0.375 | I13: 0.37083333 | J13: 0.75 | K13: 0.75347222 | L13: Asistencia | M13: =IF(OR(I13="",H13=""),"",MAX(0,ROUND((I13-H13-Parametros!$B$4)*1440,0))) -> 0 | N13: =IF(L13="Asistencia","Sin novedad",L13) -> Sin novedad | O13: Registro biométrico correcto
... A41: 46057 | B41: Miércoles | C41: EMP004 | D41: Jorge Salazar | E41: TI | F41: Soporte TI | G41: Lima | H41: 0.375 | I41: 0.36736111 | J41: 0.75 | K41: 0.76736111 | L41: Asistencia | M41: =IF(OR(I41="",H41=""),"",MAX(0,ROUND((I41-H41-Parametros!$B$4)*1440,0))) -> 0 | N41: =IF(L41="Asistencia","Sin novedad",L41) -> Sin novedad | O41: Sin novedades
A42: 46057 | B42: Miércoles | C42: EMP005 | D42: María Paredes | E42: Comercial | F42: Ejecutiva Comercial | G42: Lima | H42: 0.375 | J42: 0.75 | L42: Falta | M42: =IF(OR(I42="",H42=""),"",MAX(0,ROUND((I42-H42-Parametros!$B$4)*1440,0))) | N42: =IF(L42="Asistencia","Sin novedad",L42) -> Falta | O42: Sin justificar
A43: 46057 | B43: Miércoles | C43: EMP006 | D43: Pedro Huamán | E43: Operaciones | F43: Analista de Campo | G43: Callao | H43: 0.375 | I43: 0.38125 | J43: 0.75 | K43: 0.75625 | L43: Asistencia | M43: =IF(OR(I43="",H43=""),"",MAX(0,ROUND((I43-H43-Parametros!$B$4)*1440,0))) -> 0 | N43: =IF(L43="Asistencia","Sin novedad",L43) -> Sin novedad | O43: Sin novedades
A44: 46057 | B44: Miércoles | C44: EMP007 | D44: Daniela Núñez | E44: RRHH | F44: Coordinadora de RRHH | G44: Lima | H44: 0.375 | I44: 0.37291667 | J44: 0.75 | K44: 0.75069444 | L44: Asistencia | M44: =IF(OR(I44="",H44=""),"",MAX(0,ROUND((I44-H44-Parametros!$B$4)*1440,0))) -> 0 | N44: =IF(L44="Asistencia","Sin novedad",L44) -> Sin novedad | O44: Jornada normal
A45: 46057 | B45: Miércoles | C45: EMP008 | D45: Carlos Mejía | E45: TI | F45: Desarrollador Junior | G45: Lima | H45: 0.375 | I45: 0.375 | J45: 0.75 | K45: 0.76666667 | L45: Asistencia | M45: =IF(OR(I45="",H45=""),"",MAX(0,ROUND((I45-H45-Parametros!$B$4)*1440,0))) -> 0 | N45: =IF(L45="Asistencia","Sin novedad",L45) -> Sin novedad | O45: Registro biométrico correcto
A46: 46057 | B46: Miércoles | C46: EMP009 | D46: Valeria Soto | E46: Finanzas | F46: Analista de Tesorería | G46: Lima | H46: 0.375 | I46: 0.37152778 | J46: 0.75 | K46: 0.75 | L46: Asistencia | M46: =IF(OR(I46="",H46=""),"",MAX(0,ROUND((I46-H46-Parametros!$B$4)*1440,0))) -> 0 | N46: =IF(L46="Asistencia","Sin novedad",L46) -> Sin novedad | O46: Sin novedades
A47: 46057 | B47: Miércoles | C47: EMP010 | D47: Miguel Chávez | E47: Comercial | F47: Asesor de Ventas | G47: Surco | H47: 0.375 | I47: 0.37152778 | J47: 0.75 | K47: 0.75972222 | L47: Asistencia | M47: =IF(OR(I47="",H47=""),"",MAX(0,ROUND((I47-H47-Parametros!$B$4)*1440,0))) -> 0 | N47: =IF(L47="Asistencia","Sin novedad",L47) -> Sin novedad | O47: Registro biométrico correcto
A48: 46057 | B48: Miércoles | C48: EMP011 | D48: Sofía Quispe | E48: Operaciones | F48: Asistente Operativo | G48: Callao | H48: 0.375 | I48: 0.38680556 | J48: 0.75 | K48: 0.74652778 | L48: Tardanza | M48: =IF(OR(I48="",H48=""),"",MAX(0,ROUND((I48-H48-Parametros!$B$4)*1440,0))) -> 7 | N48: =IF(L48="Asistencia","Sin novedad",L48) -> Tardanza | O48: Ingreso fuera de tolerancia
A49: 46057 | B49: Miércoles | C49: EMP012 | D49: Ricardo León | E49: TI | F49: Administrador de Sistemas | G49: Lima | H49: 0.375 | I49: 0.36458333 | J49: 0.75 | K49: 0.75208333 | L49: Asistencia | M49: =IF(OR(I49="",H49=""),"",MAX(0,ROUND((I49-H49-Parametros!$B$4)*1440,0))) -> 0 | N49: =IF(L49="Asistencia","Sin novedad",L49) -> Sin novedad | O49: Sin novedades
A50: 46057 | B50: Miércoles | C50: EMP013 | D50: Camila Vega | E50: Comercial | F50: Analista Comercial | G50: Surco | H50: 0.375 | I50: 0.37152778 | J50: 0.75 | K50: 0.74930556 | L50: Asistencia | M50: =IF(OR(I50="",H50=""),"",MAX(0,ROUND((I50-H50-Parametros!$B$4)*1440,0))) -> 0 | N50: =IF(L50="Asistencia","Sin novedad",L50) -> Sin novedad | O50: Registro biométrico correcto
A51: 46057 | B51: Miércoles | C51: EMP014 | D51: José Cárdenas | E51: Operaciones | F51: Técnico de Operaciones | G51: Callao | H51: 0.375 | I51: 0.36388889 | J51: 0.75 | K51: 0.76111111 | L51: Asistencia | M51: =IF(OR(I51="",H51=""),"",MAX(0,ROUND((I51-H51-Parametros!$B$4)*1440,0))) -> 0 | N51: =IF(L51="Asistencia","Sin novedad",L51) -> Sin novedad | O51: Jornada normal
A52: 46057 | B52: Miércoles | C52: EMP015 | D52: Lucía Herrera | E52: Finanzas | F52: Analista Financiera | G52: Lima | H52: 0.375 | I52: 0.37430556 | J52: 0.75 | K52: 0.74166667 | L52: Asistencia | M52: =IF(OR(I52="",H52=""),"",MAX(0,ROUND((I52-H52-Parametros!$B$4)*1440,0))) -> 0 | N52: =IF(L52="Asistencia","Sin novedad",L52) -> Sin novedad | O52: Sin novedades
A53: 46057 | B53: Miércoles | C53: EMP016 | D53: Andrés Flores | E53: RRHH | F53: Auxiliar de Planillas | G53: Lima | H53: 0.375 | I53: 0.36597222 | J53: 0.75 | K53: 0.75972222 | L53: Asistencia | M53: =IF(OR(I53="",H53=""),"",MAX(0,ROUND((I53-H53-Parametros!$B$4)*1440,0))) -> 0 | N53: =IF(L53="Asistencia","Sin novedad",L53) -> Sin novedad | O53: Registro biométrico correcto
A54: 46057 | B54: Miércoles | C54: EMP017 | D54: Paola Rivas | E54: Comercial | F54: Coordinadora Comercial | G54: Surco | H54: 0.375 | I54: 0.38194444 | J54: 0.75 | K54: 0.74375 | L54: Asistencia | M54: =IF(OR(I54="",H54=""),"",MAX(0,ROUND((I54-H54-Parametros!$B$4)*1440,0))) -> 0 | N54: =IF(L54="Asistencia","Sin novedad",L54) -> Sin novedad | O54: Sin novedades
... A78: 46059 | B78: Viernes | C78: EMP005 | D78: María Paredes | E78: Comercial | F78: Ejecutiva Comercial | G78: Lima | H78: 0.375 | I78: 0.38541667 | J78: 0.75 | K78: 0.75069444 | L78: Tardanza | M78: =IF(OR(I78="",H78=""),"",MAX(0,ROUND((I78-H78-Parametros!$B$4)*1440,0))) -> 5 | N78: =IF(L78="Asistencia","Sin novedad",L78) -> Tardanza | O78: Tráfico
A79: 46059 | B79: Viernes | C79: EMP006 | D79: Pedro Huamán | E79: Operaciones | F79: Analista de Campo | G79: Callao | H79: 0.375 | J79: 0.75 | L79: Falta | M79: =IF(OR(I79="",H79=""),"",MAX(0,ROUND((I79-H79-Parametros!$B$4)*1440,0))) | N79: =IF(L79="Asistencia","Sin novedad",L79) -> Falta | O79: Inasistencia registrada
A80: 46059 | B80: Viernes | C80: EMP007 | D80: Daniela Núñez | E80: RRHH | F80: Coordinadora de RRHH | G80: Lima | H80: 0.375 | I80: 0.36527778 | J80: 0.75 | K80: 0.74305556 | L80: Asistencia | M80: =IF(OR(I80="",H80=""),"",MAX(0,ROUND((I80-H80-Parametros!$B$4)*1440,0))) -> 0 | N80: =IF(L80="Asistencia","Sin novedad",L80) -> Sin novedad | O80: Registro biométrico correcto
A81: 46059 | B81: Viernes | C81: EMP008 | D81: Carlos Mejía | E81: TI | F81: Desarrollador Junior | G81: Lima | H81: 0.375 | I81: 0.38125 | J81: 0.75 | K81: 0.74305556 | L81: Asistencia | M81: =IF(OR(I81="",H81=""),"",MAX(0,ROUND((I81-H81-Parametros!$B$4)*1440,0))) -> 0 | N81: =IF(L81="Asistencia","Sin novedad",L81) -> Sin novedad | O81: Registro biométrico correcto
A82: 46059 | B82: Viernes | C82: EMP009 | D82: Valeria Soto | E82: Finanzas | F82: Analista de Tesorería | G82: Lima | H82: 0.375 | I82: 0.36458333 | J82: 0.75 | K82: 0.75694444 | L82: Asistencia | M82: =IF(OR(I82="",H82=""),"",MAX(0,ROUND((I82-H82-Parametros!$B$4)*1440,0))) -> 0 | N82: =IF(L82="Asistencia","Sin novedad",L82) -> Sin novedad | O82: Jornada normal
A83: 46059 | B83: Viernes | C83: EMP010 | D83: Miguel Chávez | E83: Comercial | F83: Asesor de Ventas | G83: Surco | H83: 0.375 | I83: 0.37569444 | J83: 0.75 | K83: 0.74791667 | L83: Asistencia | M83: =IF(OR(I83="",H83=""),"",MAX(0,ROUND((I83-H83-Parametros!$B$4)*1440,0))) -> 0 | N83: =IF(L83="Asistencia","Sin novedad",L83) -> Sin novedad | O83: Sin novedades
A84: 46059 | B84: Viernes | C84: EMP011 | D84: Sofía Quispe | E84: Operaciones | F84: Asistente Operativo | G84: Callao | H84: 0.375 | I84: 0.37986111 | J84: 0.75 | K84: 0.74930556 | L84: Asistencia | M84: =IF(OR(I84="",H84=""),"",MAX(0,ROUND((I84-H84-Parametros!$B$4)*1440,0))) -> 0 | N84: =IF(L84="Asistencia","Sin novedad",L84) -> Sin novedad | O84: Registro biométrico correcto
A85: 46059 | B85: Viernes | C85: EMP012 | D85: Ricardo León | E85: TI | F85: Administrador de Sistemas | G85: Lima | H85: 0.375 | J85: 0.75 | L85: Permiso | M85: =IF(OR(I85="",H85=""),"",MAX(0,ROUND((I85-H85-Parametros!$B$4)*1440,0))) | N85: =IF(L85="Asistencia","Sin novedad",L85) -> Permiso | O85: Capacitación externa
A86: 46059 | B86: Viernes | C86: EMP013 | D86: Camila Vega | E86: Comercial | F86: Analista Comercial | G86: Surco | H86: 0.375 | I86: 0.37152778 | J86: 0.75 | K86: 0.75208333 | L86: Asistencia | M86: =IF(OR(I86="",H86=""),"",MAX(0,ROUND((I86-H86-Parametros!$B$4)*1440,0))) -> 0 | N86: =IF(L86="Asistencia","Sin novedad",L86) -> Sin novedad | O86: Registro biométrico correcto
A87: 46059 | B87: Viernes | C87: EMP014 | D87: José Cárdenas | E87: Operaciones | F87: Técnico de Operaciones | G87: Callao | H87: 0.375 | I87: 0.37083333 | J87: 0.75 | K87: 0.74305556 | L87: Asistencia | M87: =IF(OR(I87="",H87=""),"",MAX(0,ROUND((I87-H87-Parametros!$B$4)*1440,0))) -> 0 | N87: =IF(L87="Asistencia","Sin novedad",L87) -> Sin novedad | O87: Registro biométrico correcto
A88: 46059 | B88: Viernes | C88: EMP015 | D88: Lucía Herrera | E88: Finanzas | F88: Analista Financiera | G88: Lima | H88: 0.375 | I88: 0.37222222 | J88: 0.75 | K88: 0.75694444 | L88: Asistencia | M88: =IF(OR(I88="",H88=""),"",MAX(0,ROUND((I88-H88-Parametros!$B$4)*1440,0))) -> 0 | N88: =IF(L88="Asistencia","Sin novedad",L88) -> Sin novedad | O88: Registro biométrico correcto
A89: 46059 | B89: Viernes | C89: EMP016 | D89: Andrés Flores | E89: RRHH | F89: Auxiliar de Planillas | G89: Lima | H89: 0.375 | I89: 0.36736111 | J89: 0.75 | K89: 0.74236111 | L89: Asistencia | M89: =IF(OR(I89="",H89=""),"",MAX(0,ROUND((I89-H89-Parametros!$B$4)*1440,0))) -> 0 | N89: =IF(L89="Asistencia","Sin novedad",L89) -> Sin novedad | O89: Jornada normal
A90: 46059 | B90: Viernes | C90: EMP017 | D90: Paola Rivas | E90: Comercial | F90: Coordinadora Comercial | G90: Surco | H90: 0.375 | I90: 0.38125 | J90: 0.75 | K90: 0.74444444 | L90: Asistencia | M90: =IF(OR(I90="",H90=""),"",MAX(0,ROUND((I90-H90-Parametros!$B$4)*1440,0))) -> 0 | N90: =IF(L90="Asistencia","Sin novedad",L90) -> Sin novedad | O90: Registro biométrico correcto
...
